Workbook
Name STARTING_BALANCE: 'R&D Detailed (Batt) FY24 Ledger'!$H$4
Name STARTING_BALANCE: 'R&D HL FY22 Ledger'!$F$4
Name STARTING_BALANCE: 'R&D Detailed (Prod) FY24 Ledger'!$H$4
Name Type: '[1]Maintenance Work Order'!#REF!

Sheet R&D HL FY22 Ledger
B2: Ride Electric Wholesale
B3: Date. | C3: Financial Year 2022 - Total R&D Expenditure | F3: Total R&D Spend FY22
F4: =SUM(E14,E21,E30,E27) -> 980214.33
A8: Capital Expenditure
B9: ID# | C9: DESCRIPTION | D9: Quantity | E9: Total Cost.
B10: R&D-Prod | C10: Smartmotion Electric Bike's (R&D Bikes) | D10: ='R&D Detailed (Prod) FY24 Ledger'!D36 -> 139 | E10: ='R&D Detailed (Prod) FY24 Ledger'!G36 -> 308851.17
C11: VSETT Electric Scooters (R&D Scooters) | D11: ='R&D Detailed (Prod) FY24 Ledger'!D48 -> 53 | E11: ='R&D Detailed (Prod) FY24 Ledger'!G48 -> 120640.26
C12: ZERO Electric Scooters (R&D Scooters) | D12: ='R&D Detailed (Prod) FY24 Ledger'!D55 -> 3 | E12: ='R&D Detailed (Prod) FY24 Ledger'!G55 -> 34664.68
D14: Total | E14: =SUM(E10:E13) -> 464156.11
B15: R&D-EquipTool | C15: Glitter Spot Welder | D15: 1 | E15: 770
C16: Lab Bench Power Supply | D16: 1 | E16: 1500
C17: Battery Tester | D17: 1 | E17: 2500
D21: Total | E21: =SUM(E15:E20) -> 4770
B22: R&D-EquiptComp | C22: Lithium Ir Battery Cells - 18650 | D22: 65265 | E22: 282187.5
C23: Lithium Ir Battery Cells - 21700 | D23: 5500 | E23: =5500*7.86 -> 43230
C24: Electrical Componentry (Nickel, Wiring, Caps, ICU's) | D24: N/A | E24: 50232
C25: BMS | D25: N/A | E25: 135638.72
D27: Total | E27: =SUM(E22:E26) -> 511288.22
E30: =SUM(E28:E29) -> 0

Sheet R&D Detailed (Prod) FY24 Ledger
B2: Ride Electric Wholesale - R&D Ledger FY2024
C3: Pricing is at cost only from EBD, Invoiced at arrival. | H3: Total PEV Spend.
H4: =G36+G48+G55 -> 464156.11 | J4: =STARTING_BALANCE*18.5% -> 85868.88
B6: Date. | C6: Financial Year 2024 - Total R&D Expenditure
B8: ID# | C8: DESCRIPTION | D8: Quantity | E8: Cost Per Unit. | F8: CREDIT'S | G8: Total Cost.
C9: Smartmotion XCity MED 27.5" WHL | D9: 3 | E9: 1670.86 | G9: =E9*D9 -> 5012.58
C10: Smartmotion Pacer GT 36V 14.5Ah White Large | D10: 3 | E10: 1806.82 | G10: =E10*D10 -> 5420.46
C11: Smartmotion Essence MED 26" WHL | D11: 3 | E11: 821.73 | G11: =E11*D11 -> 2465.19
C12: Smartmotion E20 Step Thru | D12: 3 | E12: 930.89 | G12: =E12*D12 -> 2792.67 | H12: =AVERAGE(E9:E34) -> 1953.1638
C13: Smartmotion G3 EUrban MED 26" WHL | D13: 3 | E13: 1056.36 | G13: =E13*D13 -> 3169.08
C14: Smartmotion G3 ECity MED 26" WHL | D14: 3 | E14: 1056.36 | G14: =E14*D14 -> 3169.08 | H14: battery built into frame - 8
C15: Smartmotion Pacer 250W 48V | D15: 3 | E15: 1967.31 | G15: =E15*D15 -> 5901.93
C16: Smartmotion Catalyst 250W 48V | D16: 3 | E16: 1719.69 | G16: =E16*D16 -> 5159.07
C17: Smartmotion MidCity SML 24" WHL | D17: 3 | E17: 1556.74 | G17: =E17*D17 -> 4670.22
C18: Smartmotion Hypersonic Neo | D18: 3 | E18: 2361.71 | G18: =E18*D18 -> 7085.13
C19: Smartmotion Xcity Neo | D19: 4 | E19: 2063.67 | G19: =E19*D19 -> 8254.68
C20: Smartmotion Xurban Neo | D20: 4 | E20: 1827.82 | G20: =E20*D20 -> 7311.28
C21: Smartmotion Hypersonic Ultra | D21: 3 | E21: 3146.12 | G21: =E21*D21 -> 9438.36
C22: Smartmotion Renegade | D22: 8 | E22: 1509 | G22: =E22*D22 -> 12072
C23: Fatfish | D23: 8 | E23: 1409 | G23: =E23*D23 -> 11272
C24: Fatfish X | D24: 8 | E24: 1409.09 | G24: =E24*D24 -> 11272.72
C25: FatFish Dual Suspension | D25: 8 | E25: 2500 | G25: =E25*D25 -> 20000
C26: FatFish Step thr | D26: 8 | E26: 1409.09 | G26: =E26*D26 -> 11272.72
... C35: Explore Performance | D35: 6 | E35: 7225 | G35: =E35*D35 -> 43350
C36: Total Smartmotion Bikes | D36: =SUM(D9:D35) -> 139 | F36: Total cost for SM Bikes | G36: =SUM(G9:G35) -> 308851.17
C37: VSETT 11+ SUPER Electric Scooter /72V 35LG | D37: 3 | E37: 4772.05 | G37: =E37*D37 -> 14316.15
C38: VSETT 11+ Electric Scooter | D38: 3 | E38: 4090.23 | G38: =E38*D38 -> 12270.69
C39: VSETT 10+ Electric Scooter | D39: 3 | E39: 3067.5 | G39: =E39*D39 -> 9202.5
C40: VSETT 9+ Electric Scooter | D40: 3 | E40: 1772.05 | G40: =E40*D40 -> 5316.15
C41: VSETT 9 Electric Scooter | D41: 3 | E41: 1317.5 | G41: =E41*D41 -> 3952.5
C42: VSETT 8+ Electric Scooter | D42: 3 | E42: 1362.95 | G42: =E42*D42 -> 4088.85
C43: VSETT 8 Electric Scooter | D43: 3 | E43: 1431.14 | G43: =E43*D43 -> 4293.42
C44: VSETT 10 Light | D44: 8 | E44: 2000 | G44: =E44*D44 -> 16000
C45: VSETT Apex 8 | D45: 8 | E45: 1400 | G45: =E45*D45 -> 11200
C46: VSETT Apex 9 | D46: 8 | E46: 1500 | G46: =E46*D46 -> 12000
C47: VSETT Apex 10 | D47: 8 | E47: 3500 | G47: =E47*D47 -> 28000
C48: Total VSETT Scooters | D48: =SUM(D37:D47) -> 53 | F48: Total for VSETT Scooters | G48: =SUM(G37:G47) -> 120640.26
C49: ZERO 11X Electric Scooter | D49: 3 | E49: 3234.33 | G49: =E49*D49 -> 9702.99
C50: ZERO 10X Electric Scooter | D50: 3 | E50: 1971.82 | G50: =E50*D50 -> 5915.46
C51: ZERO 9 Electric Scooter | D51: 3 | E51: 688.61 | G51: =E51*D51 -> 2065.83
...

Sheet R&D Detailed (Batt) FY24 Ledger
B2: Ride Electric Wholesale - R&D Ledger FY2024
C3: Pricing is at cost only from EBD, Invoiced at arrival. | H3: Total Battery Spend.
H4: =G18+G27+G33 -> 45000
B6: Date. | C6: Financial Year 2024 - Total R&D Expenditure
B8: ID# - Li-on | C8: DESCRIPTION | D8: Quantity | E8: Cost Per Unit. | F8: CREDIT'S | G8: Total Cost.
C9: LG 18650 - INR N1 - 3500mah | D9: 5000 | E9: 2.9 | G9: =E9*D9 -> 14500
C10: SAMSUNG - 35E 3500mAh 10A | D10: 5000 | E10: 3 | G10: =E10*D10 -> 15000
C11: LG 21700 5000mAH | D11: 5000 | E11: 3.1 | G11: =E11*D11 -> 15500
E18: Total cost for Batteries | G18: =SUM(G8:G17) -> 45000
K25: 4

Sheet R&D IP Co Batteries FY23 Ledger
B2: Ride Electric IP Co PTY LTD - R&D Running Ledger (2023)
C3: Pricing is at cost only | F3: Total Battery Comp Spend.
F4: =G18+G24+G33 -> 672636.19 | G4: =F4*43.5% -> 292596.74
F5: Price in AUD
B6: Date. | C6: Financial Year 2024 - Total R&D Expenditure
B8: ID# | C8: DESCRIPTION (SMALL FORM CELLS Li-io) | D8: Quantity | E8: Cost Per Unit AUD | F8: Cost Per Unit AUD
B9: R&D-BATT-LF | C9: SAMSUNG INR18650-35E | D9: 15000 | E9: 3.83 | F9: 57450
C10: LG INR18650 MH1 | D10: 15000 | E10: 3.58 | F10: 53700
C11: LG INR21700 M50LT | D11: 15000 | E11: 4.75 | F11: 71250
E12: Total | F12: 182400
B14: ID# | C14: DESCRIPTION (LARGE FORM CELLS LifeP04) | D14: Quantity | E14: Cost Per Unit AUD | F14: Total Cost AUD
B15: R&D-BATT-LF | C15: EVE LF280Ah LiFePO04 Prismatic | D15: 400 | E15: 151.67 | F15: 60668
C16: EVE LF302Ah LiFePO04 Prismatic | D16: 400 | E16: 160.82 | F16: 64328
C17: EVE LF320 LiFePO04 Prismatic | D17: 400 | E17: 176.67 | F17: 70668
E18: Total | F18: 195664 | G18: 378064
B20: ID# | C20: DESCRIPTION (LARGE FORM CELLS LifeP04) | D20: Quantity | E20: Cost Per Unit AUD | F20: Total Cost AUD
B21: R&D-BATT-LF | C21: CATL LiFeP04 204Ah | D21: 400 | E21: 161.25 | F21: 64500
C22: CATL LiFeP04 310Ah | D22: 400 | E22: 180 | F22: 72000
C23: CATL LiFeP04 228Ah | D23: 400 | E23: 200 | F23: 80000
E24: Total | F24: 216500 | G24: =F24 -> 216500
B26: ID# | C26: DESCRIPTION (Electrical Comp) | D26: Quantity | E26: Cost Per Unit AUD | F26: Total Cost AUD
C27: Tektronix MSO2024B 200 MHz 4+16-Ch 1 GS/s Mixed Signal Oscilloscope | D27: 2 | E27: 18014.98 | F27: 36029.96
C28: Rack Mount 1000V 1200W Laboratory Adjustable Switching Programmable DC High Voltage Power Supply | D28: 2 | E28: 3567.63 | F28: 7135.26
C29: Granbo Ultrasonic Cleaner 30L 900W Power Adjustable Stainless Ultrasound Bath Electronic Parts PCB Engine Gear Lab Solution | D29: 2 | E29: 461.66 | F29: 923.32
C30: 20KW Pure Sine Wave Solar Hybrid inverter 192VDC TO 220V 110VAC 20000W With MPPT Controller Charging Power Inverter Rotatable | D30: 1 | E30: 5361.91 | F30: 5361.91
C31: MakerPi Industrial 3D Printer Large Printing Fully Closed Machine Size 310*310*450mm High Temperature For PLA /ABS Filament | D31: 3 | E31: 8070.58 | F31: 24211.74
C32: DC LV-HV Buck Converter (50,60,70,80,90,110) -> (330v) | D32: 200 | E32: 22.05 | F32: 4410
E33: Total | F33: 78072.19 | G33: =F33 -> 78072.19
